<?xml version="1.0"?>

<robot name="herkulex" xmlns:xacro="http://www.ros.org/wiki/xacro">
  <!-- Include all component files -->
  <xacro:include filename="$(find herkulex_description)/urdf/materials.urdf.xacro" />
  <!-- Define a number of dimensions using properties -->
  <xacro:property name="PI" value="3.1415926" />

  <!-- define a herkulex joint -->
  <link name="base"/>
  <joint name="fixed" type="fixed">
    <parent link="base"/>
    <child link="link1"/>
     <origin xyz="0 0 0" rpy="0 0 0"/>
  </joint>

  <link name="link1">
    <collision>
      <origin xyz="0 0 0" rpy="0 0 0"/>
      <geometry>
        <mesh filename="package://herkulex_description/meshes//0602-body.STL" scale="0.001 0.001 0.001"/>
      </geometry>
     	<material name="darkgrey"/>
    </collision>
    <visual>
      <origin xyz="0 0 0" rpy="0 0 0"/>
      <geometry>
        <mesh filename="package://herkulex_description/meshes//0602-body.STL" scale="0.001 0.001 0.001"/>
      </geometry>
      	<material name="darkgrey"/>
    </visual>
  </link>

  <joint name="joint1" type="revolute">
    <parent link="link1"/>
    <child link="horn1"/>
    <origin xyz="0 0 0" rpy="0 0 0"/>
    <axis xyz="1 0 0"/>
    <limit effort="30" lower="-2.617" upper="2.617" velocity="1.571"/>
  </joint>

  <link name="horn1">
    <collision>
      <origin xyz="0 0 0" rpy="0 0 0"/>
      <geometry>
        <mesh filename="package://herkulex_description/meshes//0602-horn.STL" scale="0.001 0.001 0.001"/>
      </geometry>
     	<material name="grey"/>
    </collision>
    <visual>
      <origin xyz="0 0 0" rpy="0 0 0"/>
      <geometry>
        <mesh filename="package://herkulex_description/meshes//0602-horn.STL" scale="0.001 0.001 0.001"/>
      </geometry>
      	<material name="grey"/>
    </visual>
  </link>


</robot>

